const Student = require('../models/student.model');

// El next es porque ya tenemos definido nuestro midlerware para gestionar los errores
// Por lo que el catch deberÃ¡ pasar el control a next con el error
const getAllStudents = async (req, res, next) => {
    try {
        const allStudents = await Student.find().populate('courses');
        return res.status(200).json(allStudents);
    } catch (error) {
        return next(error);
    }
}

const getStudentById = async (req, res) => {
    try {
        const { id } = req.params;
        const students = await Student.findById(id).populate('courses');        
        return res.status(200).json(students);
    } catch (error) {
        return next(error);
    }
}

const postNewStudent = async (req, res, next) => {
    try {

        const newStudent = new Student(req.body);
        console.log(newStudent);
        const newStudentInDB = await newStudent.save();
        return res.status(200).send(newStudentInDB);

    } catch (error) {
        return next(error);
    }
}

const pathNewCourseInStudent = async (req, res, next) => {
    try {
        const { id } = req.params;
        const idCourse = req.body.idCourse;
        const updateStudentWithCourse = await Student.findByIdAndUpdate(id, {$push: {movies:idCourse}});
        return res.status(200).json(updateStudentWithCourse);

    } catch (error) {
        return next(error);
    }
}

module.exports = { 
    getAllStudents,
    getStudentById,
    postNewStudent,
    pathNewCourseInStudent
};